<?xml version="1.0" encoding="utf-8"?>

<robot name="car1" xmlns:xacro="http://www.ros.org/wiki/xacro">

    <xacro:include filename="$(find fw-mid)/urdf/car1_macros.xacro" />
    
    <link name="base_footprint">
        <!-- <visual>
            <geometry>
                <sphere radius="0.001" />
            </geometry>
        </visual> -->
    </link>

    <link name="base_link">
        <visual>
            <geometry>
                <mesh filename="package://fw-mid/meshes/fw-mid-chassis.STL" scale="1 1 1"/>
            </geometry>
            <origin xyz="-0.34 -0.275 0.01" rpy="1.57 0 1.57" />
            <material name="white">
                <color rgba="1 1 1 1" />
            </material>
        </visual>
        <collision>
            <geometry>
                <box size="0.68 0.55 0.2" />
            </geometry>
            <origin xyz="0.0 0.0 0.0" rpy="0.0 0.0 0.0" />
        </collision>
        <inertial>
        <origin xyz="0 0 0" /> 
        <mass value="52" />
        <inertia 
            ixx="2.15" ixy="0" ixz="0"
            iyy="2.84" iyz="0"
            izz="3.31"
        />
        </inertial>

    </link>

    <joint name="base_link2base_footprint" type="fixed">
        <parent link="base_footprint" />
        <child link="base_link"/>
        <origin xyz="0 0 0.032" />
    </joint>




    <link name="left_steering_hinge">
        <visual>
            <geometry>
                <cylinder radius="0.02" length="0.005" />
            </geometry>
            <origin xyz="0 0 0" rpy="1.57 0 0" />
            <material name="black">
                <color rgba="0.0 0.0 0.0 1.0" />
            </material>
        </visual>
        <collision>
            <geometry>
                <cylinder radius="0.01" length="0.005" />
            </geometry>
            <origin xyz="0.0 0.0 0.0" rpy="1.57 0.0 0.0" />
        </collision>
        <inertial>
            <origin xyz="0 0 0" />
            <mass value="1" />
            <inertia ixx="2.7E-05" ixy="0" ixz="0" iyy="2.7E-05" iyz="0" izz="5E-05" />
        </inertial>
    </link>


    <joint name="left_steering_hinge_joint" type="revolute">
        <parent link="base_link" />
        <child link="left_steering_hinge" />
        <origin xyz="0.2 0.24 0" />
        <axis xyz="0 0 1" />
        <limit lower="-1.57" upper="1.57" effort="10.0" velocity="50.0"/>
    </joint>



    <link name="left_front_wheel">
        <visual>
            <geometry>
                <mesh filename="package://fw-mid/meshes/fw-mid-luntai.STL" scale="1 1 1"/>
            </geometry>
            <origin xyz="0.12 -0.102 0.12" rpy="1.57 1.57 -3.14" />
            <material name="black">
                <color rgba="0.0 0.0 0.0 1.0" />
            </material>
        </visual>
        <collision>
            <geometry>
                <cylinder radius="0.12" length="0.055" />
            </geometry>
            <origin xyz="0.0 0.0 0.0" rpy="1.57 0.0 0.0" />
        </collision>
        <inertial>
            <origin xyz="0 0 0" /> 
            <mass value="4" />
            <inertia 
            ixx="0.01603" ixy="0" ixz="0"
            iyy="0.01603" iyz="0"
            izz="0.0288" 
            />
        </inertial>
    </link>

    <joint name="left_front_wheel_joint" type="continuous">
        <parent link="left_steering_hinge" />
        <child link="left_front_wheel" />
        <origin xyz="0 0.0 0" />
        <axis xyz="0 1 0" />
        <limit effort="10" velocity="1000" />
    </joint>


    <link name="right_steering_hinge">
        <visual>
            <geometry>
                 <cylinder radius="0.02" length="0.005" />
            </geometry>
            <origin xyz="0 0 0" rpy="1.57 0 0" />
            <material name="black">
                <color rgba="0.0 0.0 0.0 1.0" />
            </material>
        </visual>
        <collision>
            <geometry>
                <cylinder radius="0.01" length="0.005" />
            </geometry>
            <origin xyz="0.0 0.0 0.0" rpy="1.57 0.0 0.0" />
        </collision>
        <inertial>
            <origin xyz="0 0 0" />
            <mass value="1" />
            <inertia ixx="2.7E-05" ixy="0" ixz="0" iyy="2.7E-05" iyz="0" izz="5E-05" />
        </inertial>
    </link>

    <joint name="right_steering_hinge_joint" type="revolute">
        <parent link="base_link" />
        <child link="right_steering_hinge" />
        <origin xyz="0.2 -0.24 0" />
        <axis xyz="0 0 1" />
        <limit lower="-1.57" upper="1.57" effort="10.0" velocity="50.0"/>
    </joint>


     <link name="right_front_wheel">
        <visual>
            <geometry>
                <mesh filename="package://fw-mid/meshes/fw-mid-luntai.STL" scale="1 1 1"/>
            </geometry>
            <origin xyz="-0.12 0.102 0.12" rpy="1.57 1.57 0" />
            <material name="black">
                <color rgba="0.0 0.0 0.0 1.0" />
            </material>
        </visual>
        <collision>
            <geometry>
                <cylinder radius="0.12" length="0.055" />
            </geometry>
            <origin xyz="0.0 0.0 0.0" rpy="1.57 0.0 0.0" />
        </collision>
        <inertial>
            <origin xyz="0 0 0" />
            <mass value="4" />
            <inertia 
            ixx="0.01603" ixy="0" ixz="0"
            iyy="0.01603" iyz="0"
            izz="0.0288" 
            />
        </inertial>
        <!-- <inertial>
            <origin xyz="0 0 0" />
            <mass value="1.0" />
            <inertia ixx="6.64E-04" ixy="0" ixz="0" iyy="6.64E-04" iyz="0" izz="1.02E-03" />
        </inertial> -->
    </link>

    <joint name="right_front_wheel_joint" type="continuous">
        <parent link="right_steering_hinge" />
        <child link="right_front_wheel" />
        <origin xyz="0 -0.0 0" />
        <axis xyz="0 1 0" />
        <limit effort="10" velocity="1000" />
    </joint>



    <link name="rear_left_steering_hinge">
        <visual>
            <geometry>
                <cylinder radius="0.02" length="0.005" />
            </geometry>
            <origin xyz="0 0 0" rpy="1.57 0 0" />
            <material name="black">
                <color rgba="0.0 0.0 0.0 1.0" />
            </material>
        </visual>
        <collision>
            <geometry>
                <cylinder radius="0.01" length="0.005" />
            </geometry>
            <origin xyz="0.0 0.0 0.0" rpy="1.57 0.0 0.0" />
        </collision>
        <inertial>
            <origin xyz="0 0 0" />
            <mass value="1" />
            <inertia ixx="2.7E-05" ixy="0" ixz="0" iyy="2.7E-05" iyz="0" izz="5E-05" />
        </inertial>
    </link>


    <joint name="rear_left_steering_hinge_joint" type="revolute">
        <parent link="base_link" />
        <child link="rear_left_steering_hinge" />
        <origin xyz="-0.2 0.24 0" />
        <axis xyz="0 0 1" />
        <limit lower="-1.57" upper="1.57" effort="10.0" velocity="50.0"/>
    </joint>

    <link name="left_rear_wheel">
        <visual>
            <geometry>
                <mesh filename="package://fw-mid/meshes/fw-mid-luntai.STL" scale="1 1 1"/>
            </geometry>
            <origin xyz="0.12 -0.102 0.12" rpy="1.57 1.57 3.14" />
            <material name="black">
                <color rgba="0.0 0.0 0.0 1.0" />
            </material>
        </visual>
        <collision>
            <geometry>
                <cylinder radius="0.12" length="0.055" />
            </geometry>
            <origin xyz="0.0 0.0 0.0" rpy="1.57 0.0 0.0" />
        </collision>
        <inertial>
            <origin xyz="0 0 0" /> 
            <mass value="4" />
            <inertia 
            ixx="0.01603" ixy="0" ixz="0"
            iyy="0.01603" iyz="0"
            izz="0.0288" 
            />
        </inertial>
    </link>

    <joint name="left_rear_wheel_joint" type="continuous">
        <parent link="rear_left_steering_hinge" />
        <child link="left_rear_wheel" />
        <origin xyz="0 0.0 0" />
        <axis xyz="0 1 0" />
        <limit effort="10" velocity="1000" />
    </joint>




    <link name="rear_right_steering_hinge">
        <visual>
            <geometry>
                <cylinder radius="0.02" length="0.005" />
            </geometry>
            <origin xyz="0 0 0" rpy="1.57 0 0" />
            <material name="black">
                <color rgba="0.0 0.0 0.0 1.0" />
            </material>
        </visual>
        <collision>
            <geometry>
                <cylinder radius="0.01" length="0.005" />
            </geometry>
            <origin xyz="0.0 0.0 0.0" rpy="1.57 0.0 0.0" />
        </collision>
        <inertial>
            <origin xyz="0 0 0" />
            <mass value="1" />
            <inertia ixx="2.7E-05" ixy="0" ixz="0" iyy="2.7E-05" iyz="0" izz="5E-05" />
        </inertial>
    </link>


    <joint name="rear_right_steering_hinge_joint" type="revolute">
        <parent link="base_link" />
        <child link="rear_right_steering_hinge" />
        <origin xyz="-0.2 -0.24 0" />
        <axis xyz="0 0 1" />
        <limit lower="-1.57" upper="1.57" effort="10.0" velocity="50.0"/>
    </joint>

    <link name="right_rear_wheel">
        <visual>
            <geometry>
                <mesh filename="package://fw-mid/meshes/fw-mid-luntai.STL" scale="1 1 1"/>
            </geometry>
            <origin xyz="-0.12 0.102 0.12" rpy="1.57 1.57 0" />
            <material name="black">
                <color rgba="0.0 0.0 0.0 1.0" />
            </material>
        </visual>
        <collision>
            <geometry>
                <cylinder radius="0.12" length="0.055" />
            </geometry>
            <origin xyz="0.0 0.0 0.0" rpy="1.57 0.0 0.0" />
        </collision>
        <inertial>
            <origin xyz="0 0 0" />
            <mass value="4" />
            <inertia 
            ixx="0.01603" ixy="0" ixz="0"
            iyy="0.01603" iyz="0"
            izz="0.0288" 
            />
        </inertial>
    </link>

    <joint name="right_rear_wheel_joint" type="continuous">
        <parent link="rear_right_steering_hinge" />
        <child link="right_rear_wheel" />
        <origin xyz="0 -0.0 0" />
        <axis xyz="0 1 0" />
        <limit effort="10" velocity="1000" />
    </joint>

    <!-- IMU frame -->
    <link name="imu_link"> 
        <visual> 
        <geometry> 
            <box size="0.01 0.01 0.002"/> 
        </geometry> 
        <material name="green_mat">
            <color rgba="0 1 0 1"/>
        </material>
        </visual> 
        <inertial> 
        <mass value="0.001"/> 
        <origin xyz="0 0 0"/> 
        <inertia ixx="0.0001" ixy="0.0" ixz="0.0" iyy="0.0001" iyz="0.0" izz="0.0001"/> 
        </inertial> 
    </link>

    <joint name="imu_joint" type="fixed">
        <origin xyz="0 0 0.35" rpy="0 0 0" />
        <parent link="base_link" />
        <child link="imu_link" />
    </joint>

    <gazebo reference="imu_link">
        <gravity>true</gravity>
        <sensor name="imu_sensor" type="imu">
        <always_on>true</always_on>
        <update_rate>200</update_rate>
        <visualize>true</visualize>
        <plugin filename="libgazebo_ros_imu_sensor.so" name="imu_plugin">
            <topicName>/car1_livox/imu</topicName>
            <bodyName>imu_link</bodyName>
            <updateRateHZ>200.0</updateRateHZ>
            <gaussianNoise>0.0</gaussianNoise>
            <xyzOffset>0 0 0</xyzOffset>
            <rpyOffset>0 0 0</rpyOffset>
            <frameName>imu_link</frameName>
            <initialOrientationAsReference>false</initialOrientationAsReference>
        </plugin>
        <pose>0 0 0 0 0 0</pose>
        </sensor>
    </gazebo>

        <!-- mid360 frame -->
    <link name="mid360_link"> 
        <visual> 
        <geometry> 
            <mesh filename="package://fw-mid/meshes/livox_mid-360-90x.dae" scale="1 1 1"/>
        </geometry> 
        <material name="green_mat">
            <color rgba="1 0 0 1"/>
        </material>
        </visual> 
        <inertial> 
        <mass value="0.001"/> 
        <origin xyz="0 0 0" rpy="0 0 0"/> 
        <inertia ixx="0.0001" ixy="0.0" ixz="0.0" iyy="0.0001" iyz="0.0" izz="0.0001"/> 
        </inertial> 
    </link>

    <joint name="mid360_joint" type="fixed">
        <origin xyz="-0.011 -0.02329 0" rpy="0 0 3.1415926" />
        <parent link="imu_link" />
        <child link="mid360_link" />
    </joint>

    <gazebo reference="mid360_link">
        <gravity>true</gravity>
        <sensor type="ray" name="laser_livox">
            <pose>0 0 0.04412 0 0 0</pose>
            <visualize>true</visualize>
            <always_on>True</always_on>
            <update_rate>10</update_rate>
            <plugin name="gazebo_ros_laser_controller" filename="package://fw-mid/meshes/liblivox_laser_simulation.so">
            <ray>
                <scan>
                <horizontal>
                    <samples>100</samples>
                    <resolution>1</resolution>
                    <min_angle>-3.1415926535897931</min_angle>
                    <max_angle>3.1415926535897931</max_angle>
                </horizontal>
                <vertical>
                    <samples>50</samples>
                    <resolution>1</resolution>
                    <min_angle>-3.1415926535897931</min_angle>
                    <max_angle>3.1415926535897931</max_angle>
                </vertical>
                </scan>
                <range>
                <min>0.1</min>
                <max>10</max>
                <resolution>1</resolution>
                </range>
                <noise>
                <type>gaussian</type>
                <mean>0.0</mean>
                <stddev>0.0</stddev>
                </noise>
            </ray>
                <visualize>false</visualize>
                <samples>20000</samples>
                <downsample>1</downsample>
                <csv_file_name>mid360-real-centr.csv</csv_file_name>
                <publish_pointcloud_type>3</publish_pointcloud_type>
                <ros_topic>/car1_livox/lidar</ros_topic>
                <frameName>mid360_link</frameName>
            </plugin>
            </sensor>
    </gazebo>




    <xacro:include filename="$(find fw-mid)/urdf/car1_fw-mid.gazebo" />

</robot>